15-01-2021:00:53:47 INFO     [relay.py:57  ] sgx wallet addr: 0x495c60DefDB81F719b7949114F84E65Af8FaCF86
15-01-2021:00:53:47 INFO     [relay.py:58  ] tc contract addr: 0xefEf6DffdB1a6096FE0A98E8a4c407fB64Ca680B
15-01-2021:00:53:49 INFO     [relay.py:68  ] connected to Geth/node01/v1.9.25-stable/darwin-amd64/go1.15.5
15-01-2021:00:53:49 INFO     [relay.py:93  ] filter for RequestInfo created, fromBlock=0, ID 0x8a845fd4d5be7ceadf053002e590c533.
15-01-2021:00:53:53 INFO     [relay.py:82  ] response from enclave: f8ea03850ba43b7400832dc6c094efef6dffdb1a6096fe0a98e8a4c407fb64ca680b80b884487a6e3200000000000000000000000000000000000000000000000000000000000000018deed2e07ec6d16d55febc830bdbeba51ba9a26662cd08a22afda1b9c8bfa66100000000000000000000000000000000000000000000000000000000000000007b227265766976652d302d30223a7b2268746d6c223a2253706f6e736f7265641ba0519a46cf56f8869d882da4090e5cd696a86e283e59afa97542bfd5d6afab368ea063301b9b01cf565bcffb845d9b9b29ccdde1182178b810d2372c6bb6b787f231
15-01-2021:00:53:55 INFO     [relay.py:88  ] response sent and mined: 0x155942412ab1bd9fe1966961ba59946a45103a97a8911d3d2abe489ce8b2cbfc
15-01-2021:00:54:09 ERROR    [relay.py:119 ] exception: HTTPConnectionPool(host='localhost', port=8000): Max retries exceeded with url: / (Caused by NewConnectionError('<urllib3.connection.HTTPConnection object at 0x112079190>: Failed to establish a new connection: [Errno 61] Connection refused'))
15-01-2021:00:54:11 ERROR    [relay.py:119 ] exception: HTTPConnectionPool(host='localhost', port=8000): Max retries exceeded with url: / (Caused by NewConnectionError('<urllib3.connection.HTTPConnection object at 0x10dfbfc10>: Failed to establish a new connection: [Errno 61] Connection refused'))
15-01-2021:00:54:13 ERROR    [relay.py:119 ] exception: HTTPConnectionPool(host='localhost', port=8000): Max retries exceeded with url: / (Caused by NewConnectionError('<urllib3.connection.HTTPConnection object at 0x112079280>: Failed to establish a new connection: [Errno 61] Connection refused'))
15-01-2021:00:54:15 ERROR    [relay.py:119 ] exception: HTTPConnectionPool(host='localhost', port=8000): Max retries exceeded with url: / (Caused by NewConnectionError('<urllib3.connection.HTTPConnection object at 0x11209d0d0>: Failed to establish a new connection: [Errno 61] Connection refused'))
15-01-2021:00:54:17 ERROR    [relay.py:119 ] exception: HTTPConnectionPool(host='localhost', port=8000): Max retries exceeded with url: / (Caused by NewConnectionError('<urllib3.connection.HTTPConnection object at 0x1120790a0>: Failed to establish a new connection: [Errno 61] Connection refused'))
15-01-2021:00:54:19 ERROR    [relay.py:119 ] exception: HTTPConnectionPool(host='localhost', port=8000): Max retries exceeded with url: / (Caused by NewConnectionError('<urllib3.connection.HTTPConnection object at 0x10dfbfc40>: Failed to establish a new connection: [Errno 61] Connection refused'))
15-01-2021:00:54:21 ERROR    [relay.py:119 ] exception: HTTPConnectionPool(host='localhost', port=8000): Max retries exceeded with url: / (Caused by NewConnectionError('<urllib3.connection.HTTPConnection object at 0x10dfbfd90>: Failed to establish a new connection: [Errno 61] Connection refused'))
15-01-2021:00:54:23 ERROR    [relay.py:119 ] exception: HTTPConnectionPool(host='localhost', port=8000): Max retries exceeded with url: / (Caused by NewConnectionError('<urllib3.connection.HTTPConnection object at 0x10df37a00>: Failed to establish a new connection: [Errno 61] Connection refused'))
15-01-2021:00:54:25 ERROR    [relay.py:119 ] exception: HTTPConnectionPool(host='localhost', port=8000): Max retries exceeded with url: / (Caused by NewConnectionError('<urllib3.connection.HTTPConnection object at 0x11209d1f0>: Failed to establish a new connection: [Errno 61] Connection refused'))
15-01-2021:00:54:27 ERROR    [relay.py:119 ] exception: HTTPConnectionPool(host='localhost', port=8000): Max retries exceeded with url: / (Caused by NewConnectionError('<urllib3.connection.HTTPConnection object at 0x1120905e0>: Failed to establish a new connection: [Errno 61] Connection refused'))
15-01-2021:00:54:29 ERROR    [relay.py:119 ] exception: HTTPConnectionPool(host='localhost', port=8000): Max retries exceeded with url: / (Caused by NewConnectionError('<urllib3.connection.HTTPConnection object at 0x10df1e2e0>: Failed to establish a new connection: [Errno 61] Connection refused'))
15-01-2021:00:54:31 ERROR    [relay.py:119 ] exception: HTTPConnectionPool(host='localhost', port=8000): Max retries exceeded with url: / (Caused by NewConnectionError('<urllib3.connection.HTTPConnection object at 0x1120ad250>: Failed to establish a new connection: [Errno 61] Connection refused'))
15-01-2021:00:54:33 ERROR    [relay.py:119 ] exception: HTTPConnectionPool(host='localhost', port=8000): Max retries exceeded with url: / (Caused by NewConnectionError('<urllib3.connection.HTTPConnection object at 0x10def0b50>: Failed to establish a new connection: [Errno 61] Connection refused'))
15-01-2021:00:54:35 ERROR    [relay.py:119 ] exception: HTTPConnectionPool(host='localhost', port=8000): Max retries exceeded with url: / (Caused by NewConnectionError('<urllib3.connection.HTTPConnection object at 0x112090070>: Failed to establish a new connection: [Errno 61] Connection refused'))
15-01-2021:00:54:37 ERROR    [relay.py:119 ] exception: HTTPConnectionPool(host='localhost', port=8000): Max retries exceeded with url: / (Caused by NewConnectionError('<urllib3.connection.HTTPConnection object at 0x1120906a0>: Failed to establish a new connection: [Errno 61] Connection refused'))
15-01-2021:00:54:39 ERROR    [relay.py:119 ] exception: HTTPConnectionPool(host='localhost', port=8000): Max retries exceeded with url: / (Caused by NewConnectionError('<urllib3.connection.HTTPConnection object at 0x10def0b50>: Failed to establish a new connection: [Errno 61] Connection refused'))
15-01-2021:00:54:41 ERROR    [relay.py:119 ] exception: HTTPConnectionPool(host='localhost', port=8000): Max retries exceeded with url: / (Caused by NewConnectionError('<urllib3.connection.HTTPConnection object at 0x11209d580>: Failed to establish a new connection: [Errno 61] Connection refused'))
15-01-2021:00:54:43 ERROR    [relay.py:119 ] exception: HTTPConnectionPool(host='localhost', port=8000): Max retries exceeded with url: / (Caused by NewConnectionError('<urllib3.connection.HTTPConnection object at 0x10dfbfdf0>: Failed to establish a new connection: [Errno 61] Connection refused'))
15-01-2021:00:54:45 ERROR    [relay.py:119 ] exception: HTTPConnectionPool(host='localhost', port=8000): Max retries exceeded with url: / (Caused by NewConnectionError('<urllib3.connection.HTTPConnection object at 0x112079310>: Failed to establish a new connection: [Errno 61] Connection refused'))
15-01-2021:00:54:47 ERROR    [relay.py:119 ] exception: HTTPConnectionPool(host='localhost', port=8000): Max retries exceeded with url: / (Caused by NewConnectionError('<urllib3.connection.HTTPConnection object at 0x1120ad910>: Failed to establish a new connection: [Errno 61] Connection refused'))
15-01-2021:00:54:49 ERROR    [relay.py:119 ] exception: HTTPConnectionPool(host='localhost', port=8000): Max retries exceeded with url: / (Caused by NewConnectionError('<urllib3.connection.HTTPConnection object at 0x112090910>: Failed to establish a new connection: [Errno 61] Connection refused'))
15-01-2021:00:54:51 ERROR    [relay.py:119 ] exception: HTTPConnectionPool(host='localhost', port=8000): Max retries exceeded with url: / (Caused by NewConnectionError('<urllib3.connection.HTTPConnection object at 0x11209da00>: Failed to establish a new connection: [Errno 61] Connection refused'))
15-01-2021:00:54:53 ERROR    [relay.py:119 ] exception: HTTPConnectionPool(host='localhost', port=8000): Max retries exceeded with url: / (Caused by NewConnectionError('<urllib3.connection.HTTPConnection object at 0x10dfbfc40>: Failed to establish a new connection: [Errno 61] Connection refused'))
15-01-2021:00:54:55 ERROR    [relay.py:119 ] exception: HTTPConnectionPool(host='localhost', port=8000): Max retries exceeded with url: / (Caused by NewConnectionError('<urllib3.connection.HTTPConnection object at 0x112090ee0>: Failed to establish a new connection: [Errno 61] Connection refused'))
